[2025-04-10 20:07:37] INFO ballsdex: Tortoise ORM and database ready.
[2025-04-10 20:07:37] WARNING ballsdex: Cannot add signal handler for SIGTERM.
[2025-04-10 20:07:37] INFO ballsdex: Initialized bot, connecting to Discord...
[2025-04-10 20:07:37] INFO discord.client: logging in using static token
[2025-04-10 20:07:37] INFO ballsdex.core.bot: Starting up with None shards...
[2025-04-10 20:07:38] INFO discord.gateway: Shard ID 0 has connected to Gateway (Session ID: 2756c1cde76c038b0516d4ca4ba266a7).
[2025-04-10 20:07:40] INFO ballsdex.core.bot: Successfully logged in as ArdaDex#6701 (1360020165269655682)!
[2025-04-10 20:07:40] INFO ballsdex.core.bot: jimbo_of_macedonia is the owner of this bot.
[2025-04-10 20:07:41] INFO ballsdex.core.bot: Cache loaded, summary displayed below:
[2025-04-10 20:07:41] INFO ballsdex.core.bot: Loading packages...
[2025-04-10 20:07:41] INFO ballsdex.packages.countryballs: Loaded 0 guilds in cache.
[2025-04-10 20:07:41] INFO ballsdex.core.bot: Packages loaded: admin, balls, config, countryballs, info, players, trade
[2025-04-10 20:07:44] INFO ballsdex.core.bot: Synced 6 commands.
[2025-04-10 20:07:44] INFO ballsdex.core.metrics: Prometheus server started on http://0.0.0.0:15260/
[2025-04-10 21:01:08] WARNING discord.gateway: Shard ID 0 has stopped responding to the gateway. Closing and restarting.
[2025-04-10 21:01:08] ERROR discord.shard: Attempting a reconnect for shard ID 0 in 0.53s
Traceback (most recent call last):
  File "C:\Users\jenni\AppData\Local\pypoetry\Cache\virtualenvs\ballsdex-mY-M4r6f-py3.13\Lib\site-packages\aiohttp\connector.py", line 1345, in _create_direct_connection
    hosts = await self._resolve_host(host, port, traces=traces)
            ^^^^^^^^^^^^^^^^^^^^^^^^^^^^^^^^^^^^^^^^^^^^^^^^^^^
  File "C:\Users\jenni\AppData\Local\pypoetry\Cache\virtualenvs\ballsdex-mY-M4r6f-py3.13\Lib\site-packages\aiohttp\connector.py", line 989, in _resolve_host
    return await asyncio.shield(resolved_host_task)
           ^^^^^^^^^^^^^^^^^^^^^^^^^^^^^^^^^^^^^^^^
  File "C:\Users\jenni\AppData\Local\pypoetry\Cache\virtualenvs\ballsdex-mY-M4r6f-py3.13\Lib\site-packages\aiohttp\connector.py", line 1020, in _resolve_host_with_throttle
    addrs = await self._resolver.resolve(host, port, family=self._family)
            ^^^^^^^^^^^^^^^^^^^^^^^^^^^^^^^^^^^^^^^^^^^^^^^^^^^^^^^^^^^^^
  File "C:\Users\jenni\AppData\Local\pypoetry\Cache\virtualenvs\ballsdex-mY-M4r6f-py3.13\Lib\site-packages\aiohttp\resolver.py", line 36, in resolve
    infos = await self._loop.getaddrinfo(
            ^^^^^^^^^^^^^^^^^^^^^^^^^^^^^
    ...<5 lines>...
    )
    ^
  File "C:\Python313\Lib\asyncio\base_events.py", line 934, in getaddrinfo
    return await self.run_in_executor(
           ^^^^^^^^^^^^^^^^^^^^^^^^^^^
        None, getaddr_func, host, port, family, type, proto, flags)
        ^^^^^^^^^^^^^^^^^^^^^^^^^^^^^^^^^^^^^^^^^^^^^^^^^^^^^^^^^^^
  File "C:\Python313\Lib\concurrent\futures\thread.py", line 59, in run
    result = self.fn(*self.args, **self.kwargs)
  File "C:\Python313\Lib\socket.py", line 975, in getaddrinfo
    for res in _socket.getaddrinfo(host, port, family, type, proto, flags):
               ~~~~~~~~~~~~~~~~~~~^^^^^^^^^^^^^^^^^^^^^^^^^^^^^^^^^^^^^^^^
socket.gaierror: [Errno 11001] getaddrinfo failed

The above exception was the direct cause of the following exception:

Traceback (most recent call last):
  File "C:\Users\jenni\AppData\Local\pypoetry\Cache\virtualenvs\ballsdex-mY-M4r6f-py3.13\Lib\site-packages\discord\shard.py", line 195, in reidentify
    self.ws = await asyncio.wait_for(coro, timeout=60.0)
              ^^^^^^^^^^^^^^^^^^^^^^^^^^^^^^^^^^^^^^^^^^
  File "C:\Python313\Lib\asyncio\tasks.py", line 507, in wait_for
    return await fut
           ^^^^^^^^^
  File "C:\Users\jenni\AppData\Local\pypoetry\Cache\virtualenvs\ballsdex-mY-M4r6f-py3.13\Lib\site-packages\discord\gateway.py", line 375, in from_client
    socket = await client.http.ws_connect(str(url))
             ^^^^^^^^^^^^^^^^^^^^^^^^^^^^^^^^^^^^^^
  File "C:\Users\jenni\AppData\Local\pypoetry\Cache\virtualenvs\ballsdex-mY-M4r6f-py3.13\Lib\site-packages\discord\http.py", line 554, in ws_connect
    return await self.__session.ws_connect(url, **kwargs)
           ^^^^^^^^^^^^^^^^^^^^^^^^^^^^^^^^^^^^^^^^^^^^^^
  File "C:\Users\jenni\AppData\Local\pypoetry\Cache\virtualenvs\ballsdex-mY-M4r6f-py3.13\Lib\site-packages\aiohttp\client.py", line 1002, in _ws_connect
    resp = await self.request(
           ^^^^^^^^^^^^^^^^^^^
    ...<11 lines>...
    )
    ^
  File "C:\Users\jenni\AppData\Local\pypoetry\Cache\virtualenvs\ballsdex-mY-M4r6f-py3.13\Lib\site-packages\aiohttp\client.py", line 701, in _request
    conn = await self._connector.connect(
           ^^^^^^^^^^^^^^^^^^^^^^^^^^^^^^
        req, traces=traces, timeout=real_timeout
        ^^^^^^^^^^^^^^^^^^^^^^^^^^^^^^^^^^^^^^^^
    )
    ^
  File "C:\Users\jenni\AppData\Local\pypoetry\Cache\virtualenvs\ballsdex-mY-M4r6f-py3.13\Lib\site-packages\aiohttp\connector.py", line 544, in connect
    proto = await self._create_connection(req, traces, timeout)
            ^^^^^^^^^^^^^^^^^^^^^^^^^^^^^^^^^^^^^^^^^^^^^^^^^^^
  File "C:\Users\jenni\AppData\Local\pypoetry\Cache\virtualenvs\ballsdex-mY-M4r6f-py3.13\Lib\site-packages\aiohttp\connector.py", line 1050, in _create_connection
    _, proto = await self._create_direct_connection(req, traces, timeout)
               ^^^^^^^^^^^^^^^^^^^^^^^^^^^^^^^^^^^^^^^^^^^^^^^^^^^^^^^^^^
  File "C:\Users\jenni\AppData\Local\pypoetry\Cache\virtualenvs\ballsdex-mY-M4r6f-py3.13\Lib\site-packages\aiohttp\connector.py", line 1351, in _create_direct_connection
    raise ClientConnectorDNSError(req.connection_key, exc) from exc
aiohttp.client_exceptions.ClientConnectorDNSError: Cannot connect to host gateway-us-east1-d.discord.gg:443 ssl:default [getaddrinfo failed]
[2025-04-10 21:01:22] INFO discord.gateway: Shard ID 0 has connected to Gateway (Session ID: 577aa0276252cce2a72046a5c6e7db73).
